Workbook

Sheet Hoja1
B1: GRADO QUIRÚRGICO S.A DE C.V RFC: GQU210304NJ5, Calle Central de Abastos Nave F, Local 21, San Vicente Chicoloapan de Juárez Centro, Chicoloapan, CP. 56370, EDOMEX. | E1: FECHA DE PEDIDO: | G1: CONDICIONES DE PAGO: | I1: SUCURSAL DESTINO:
A2: PROVEEDOR: | E2: CANTIDAD DE PRODUCTOS: | G2: No. DE ORDEN DE COMPRA: | I2: NO. COTIZACIÓN:
J3: REPARTO
A4: CÓDIGO | B4: DESCRIPCIÓN | C4: PIEZAS | D4: UNITARIO BRUTO | E4: PRECIO | F4: TOTAL | G4: IMPUESTOS | H4: TOTAL BRUTO | I4: IMPUESTOS | J4: F37 | K4: F35 | L4: GH | M4: SV | N4: ECA | S4: 28 COSMETICS | T4: Pago inmediato | U4: Ecatepec
D5: =E5/G5 -> 0 | F5: =C5*E5 -> 0 | G5: =IF(_xlfn.XLOOKUP(A5,MACHOTE!A:A,MACHOTE!V:V,0,0)="S",1.16,IF(_xlfn.XLOOKUP(A5,MACHOTE!A:A,MACHOTE!Y:Y,0,0)="S",1.08,1)) -> 1 | H5: =D5*C5 -> 0 | I5: =F5-H5 -> 0 | S5: ALEJANDRO MARTINEZ PONCE | T5: 15 días | U5: Iztapalapa F35
S6: Alejandro Villagomez Castro | T6: 21 días | U6: Iztapalapa F37
S7: BRONCOLIN | T7: 30 días | U7: Iztapalapa GH
S8: BRUDIFARMA | T8: 45 días | U8: San Vicente
S9: CARLOS ANTONIO ZUÑIGA ORTEGA | T9: Fin del siguiente mes | U9: CEDIS IZTAPALAPA GH
S10: CETUS FARMACEUTICA | T10: 10 días después del fin del siguiente mes | U10: CEDIS San Vicente
S11: COMERCIAL G.F.C. | T11: 30% ahora, el resto en 60 días
S12: COMERCIALIZADORA COYOQUIMEX DEL BAJIO | T12: 2/7 neto 30
S13: COMERCIALIZADORA DIBAR | T13: 90 días, en el día 10
S14: CORPORACION NACIONAL DE ABASTO FARMACEUTICOS | T14: 13 días
S15: Cristobal Mendoza Lopez | T15: 7 días
S16: DENTILAB | T16: 60 días
S17: DIANA ALEJANDRA GUZMAN MIRANDA
S18: DIFARMER
S19: DISAGS FARMACEUTICA
S20: DISTRIBUCION FARMACEUTICA YALESA
S21: DISTRIBUCIONES MDMX GDL
S22: DISTRIBUIDORA BIOLIFE
S23: DISTRIBUIDORA FARMACEUTICA CALDERON
S24: Dylan Villagomez Johnson
S25: EMANUEL ATAI REYES LEWIS
S26: Ecatepec
S27: FARMA CRÜE
S28: FARMA GENEX
... S69: sandrareyesramirez@gmail.com

Sheet OC
B1: GRADO QUIRÚRGICO S.A DE C.V RFC: GQU210304NJ5, Calle Central de Abastos Nave F, Local 21, San Vicente Chicoloapan de Juárez Centro, Chicoloapan, CP. 56370, EDOMEX.
A2: PROVEEDOR:
A3: FECHA DE PEDIDO:
A4: CONDICIONES DE PAGO:
A5: No. DE ORDEN DE COMPRA:
A6: SUCURSAL DESTINO: | S6: ALEJANDRO VILLAGOMEZ
A7: CLASE DE MOVIMIENTO | S7: MIGUEL ANGEL REYES MENDIETA
A8: FOLIO COTIZACIÓN | J8: REPARTO | S8: RICARDO HEREDIA
A9: CÓDIGO | B9: DESCRIPCIÓN | C9: PIEZAS | D9: UNITARIO BRUTO | E9: PRECIO MXN | F9: TOTAL | G9: IMPUESTOS | H9: TOTAL BRUTO | I9: IMPUESTOS | J9: F37 | K9: F35 | L9: GH | M9: SV | N9: ECA | P9: FACTOR | S9: 28 COSMETICS | T9: Pago inmediato | U9: Ecatepec
D10: =E10/G10 -> 0 | F10: =C10*E10 -> 0 | G10: =IF(_xlfn.XLOOKUP(A10,MACHOTE!A:A,MACHOTE!V:V,0,0)="S",1.16,IF(_xlfn.XLOOKUP(A10,MACHOTE!A:A,MACHOTE!Y:Y,0,0)="S",1.08,1)) -> 1 | H10: =D10*C10 -> 0 | I10: =F10-H10 -> 0 | S10: ALEJANDRO MARTINEZ PONCE | T10: 15 días | U10: Iztapalapa F35
D11: =E11/G11 -> 0 | F11: =C11*E11 -> 0 | G11: =IF(_xlfn.XLOOKUP(A11,MACHOTE!A:A,MACHOTE!V:V,0,0)="S",1.16,IF(_xlfn.XLOOKUP(A11,MACHOTE!A:A,MACHOTE!Y:Y,0,0)="S",1.08,1)) -> 1 | H11: =D11*C11 -> 0 | I11: =F11-H11 -> 0 | S11: SANFER | T11: 21 días | U11: Iztapalapa F37
S12: BRONCOLIN | T12: 30 días | U12: Iztapalapa GH
S13: BRUDIFARMA | T13: 45 días | U13: San Vicente
S14: CARLOS ANTONIO ZUÑIGA ORTEGA | T14: Fin del siguiente mes | U14: CEDIS IZTAPALAPA GH
S15: CETUS FARMACEUTICA | T15: 10 días después del fin del siguiente mes | U15: CEDIS San Vicente
S16: COMERCIAL G.F.C. | T16: 30% ahora, el resto en 60 días
S17: COMERCIALIZADORA COYOQUIMEX DEL BAJIO | T17: 2/7 neto 30
S18: COMERCIALIZADORA DIBAR | T18: 90 días, en el día 10
S19: CORPORACION NACIONAL DE ABASTO FARMACEUTICOS | T19: 13 días
S20: Cristobal Mendoza Lopez | T20: 7 días
S21: DENTILAB DL | T21: 60 días
S22: DIANA ALEJANDRA GUZMAN MIRANDA
S23: DIFARMER
S24: DISAGS FARMACEUTICA
S25: DISTRIBUCION FARMACEUTICA YALESA
S26: DISTRIBUCIONES MDMX GDL
S27: DISTRIBUIDORA BIOLIFE
S28: DISTRIBUIDORA FARMACEUTICA CALDERON
S29: Dylan Villagomez Johnson
S30: EMANUEL ATAI REYES LEWIS
S31: Ecatepec
S32: FARMA CRÜE
S33: FARMA GENEX
... S77: REBOTICA MADRID

Sheet lay out
A1: CODIGO | B1: DESCRIPCIÓN | C1: PIEZAS | D1: MULTIPLO DE COMPRA | E1: UNITARIO BRUTO | F1: PRECIO | G1: TOTAL | H1: IMPUESTOS | I1: TOTAL BRUTO | J1: IMPUESTOS | K1: SUCURSAL DESTINO | L1: CLASE DE MOVIMIENTO | M1: PROVEEDOR | N1: FECHA DE PEDIDO | O1: No. DE ORDEN DE COMPRA | P1: FOLIO COTIZACIÓN | Q1: CONDICION DE PAGO | R1: F37 | S1: F35 | T1: GH | U1: SV | V1: ECA
A2: =OC!A10 -> 0 | B2: =OC!B10 -> 0 | C2: =OC!C10 -> 0 | D2: =OC!P10 -> 0 | E2: =OC!D10 -> 0 | F2: =OC!E10 -> 0 | G2: =C2*F2 -> 0 | H2: =IF(_xlfn.XLOOKUP(A2,[1]MACHOTE!A:A,[1]MACHOTE!V:V,0,0)="S",1.16,IF(_xlfn.XLOOKUP(A2,[1]MACHOTE!A:A,[1]MACHOTE!Y:Y,0,0)="S",1.08,1)) -> 1 | I2: =E2*C2 -> 0 | J2: =G2-I2 -> 0 | K2: =OC!$B$6 -> 0 | L2: =OC!$B$7 -> 0 | M2: =OC!$B$2 -> 0 | N2: =OC!$B$3 -> 0 | O2: =OC!$B$5 -> 0 | P2: =OC!$B$8 -> 0 | Q2: =OC!$B$4 -> 0 | R2: =OC!J10 -> 0 | S2: 0 | T2: =OC!L10 -> 0 | U2: =OC!M10 -> 0 | V2: =OC!N10 -> 0
A3: =OC!A11 -> 0 | B3: =OC!B11 -> 0 | C3: =OC!C11 -> 0 | D3: =OC!P11 -> 0 | E3: =OC!D11 -> 0 | F3: =OC!E11 -> 0 | G3: =C3*F3 -> 0 | H3: =IF(_xlfn.XLOOKUP(A3,[1]MACHOTE!A:A,[1]MACHOTE!V:V,0,0)="S",1.16,IF(_xlfn.XLOOKUP(A3,[1]MACHOTE!A:A,[1]MACHOTE!Y:Y,0,0)="S",1.08,1)) -> 1 | I3: =E3*C3 -> 0 | J3: =G3-I3 -> 0 | K3: =OC!$B$6 -> 0 | L3: =OC!$B$7 -> 0 | M3: =OC!$B$2 -> 0 | N3: =OC!$B$3 -> 0 | O3: =OC!$B$5 -> 0 | P3: =OC!$B$8 -> 0 | Q3: =OC!$B$4 -> 0 | R3: =OC!J11 -> 0 | S3: 0 | T3: =OC!M11 -> 0 | U3: =OC!N11 -> 0 | V3: =OC!N11 -> 0
A4: =OC!A12 -> 0 | B4: =OC!B12 -> 0 | C4: =OC!C12 -> 0 | D4: =OC!P12 -> 0 | E4: =OC!D12 -> 0 | F4: =OC!E12 -> 0 | G4: =C4*F4 -> 0 | H4: =IF(_xlfn.XLOOKUP(A4,[1]MACHOTE!A:A,[1]MACHOTE!V:V,0,0)="S",1.16,IF(_xlfn.XLOOKUP(A4,[1]MACHOTE!A:A,[1]MACHOTE!Y:Y,0,0)="S",1.08,1)) -> 1 | I4: =E4*C4 -> 0 | J4: =G4-I4 -> 0 | K4: =OC!$B$6 -> 0 | L4: =OC!$B$7 -> 0 | M4: =OC!$B$2 -> 0 | N4: =OC!$B$3 -> 0 | O4: =OC!$B$5 -> 0 | P4: =OC!$B$8 -> 0 | Q4: =OC!$B$4 -> 0 | R4: =OC!J12 -> 0 | S4: 0 | T4: =OC!M12 -> 0 | U4: =OC!N12 -> 0 | V4: =OC!N12 -> 0
A5: =OC!A13 -> 0 | B5: =OC!B13 -> 0 | C5: =OC!C13 -> 0 | D5: =OC!P13 -> 0 | E5: =OC!D13 -> 0 | F5: =OC!E13 -> 0 | G5: =C5*F5 -> 0 | H5: =IF(_xlfn.XLOOKUP(A5,[1]MACHOTE!A:A,[1]MACHOTE!V:V,0,0)="S",1.16,IF(_xlfn.XLOOKUP(A5,[1]MACHOTE!A:A,[1]MACHOTE!Y:Y,0,0)="S",1.08,1)) -> 1 | I5: =E5*C5 -> 0 | J5: =G5-I5 -> 0 | K5: =OC!$B$6 -> 0 | L5: =OC!$B$7 -> 0 | M5: =OC!$B$2 -> 0 | N5: =OC!$B$3 -> 0 | O5: =OC!$B$5 -> 0 | P5: =OC!$B$8 -> 0 | Q5: =OC!$B$4 -> 0 | R5: =OC!J13 -> 0 | S5: 0 | T5: =OC!L13 -> 0 | U5: =OC!M13 -> 0 | V5: =OC!N13 -> 0
A6: =OC!A14 -> 0 | B6: =OC!B14 -> 0 | C6: =OC!C14 -> 0 | D6: =OC!P14 -> 0 | E6: =OC!D14 -> 0 | F6: =OC!E14 -> 0 | G6: =C6*F6 -> 0 | H6: =IF(_xlfn.XLOOKUP(A6,[1]MACHOTE!A:A,[1]MACHOTE!V:V,0,0)="S",1.16,IF(_xlfn.XLOOKUP(A6,[1]MACHOTE!A:A,[1]MACHOTE!Y:Y,0,0)="S",1.08,1)) -> 1 | I6: =E6*C6 -> 0 | J6: =G6-I6 -> 0 | K6: =OC!$B$6 -> 0 | L6: =OC!$B$7 -> 0 | M6: =OC!$B$2 -> 0 | N6: =OC!$B$3 -> 0 | O6: =OC!$B$5 -> 0 | P6: =OC!$B$8 -> 0 | Q6: =OC!$B$4 -> 0 | R6: =OC!J14 -> 0 | S6: 0 | T6: =OC!L14 -> 0 | U6: =OC!M14 -> 0 | V6: =OC!N14 -> 0
A7: =OC!A15 -> 0 | B7: =OC!B15 -> 0 | C7: =OC!C15 -> 0 | D7: =OC!P15 -> 0 | E7: =OC!D15 -> 0 | F7: =OC!E15 -> 0 | G7: =C7*F7 -> 0 | H7: =IF(_xlfn.XLOOKUP(A7,[1]MACHOTE!A:A,[1]MACHOTE!V:V,0,0)="S",1.16,IF(_xlfn.XLOOKUP(A7,[1]MACHOTE!A:A,[1]MACHOTE!Y:Y,0,0)="S",1.08,1)) -> 1 | I7: =E7*C7 -> 0 | J7: =G7-I7 -> 0 | K7: =OC!$B$6 -> 0 | L7: =OC!$B$7 -> 0 | M7: =OC!$B$2 -> 0 | N7: =OC!$B$3 -> 0 | O7: =OC!$B$5 -> 0 | P7: =OC!$B$8 -> 0 | Q7: =OC!$B$4 -> 0 | R7: =OC!J15 -> 0 | S7: 0 | T7: =OC!L15 -> 0 | U7: =OC!M15 -> 0 | V7: =OC!N15 -> 0
A8: =OC!A16 -> 0 | B8: =OC!B16 -> 0 | C8: =OC!C16 -> 0 | D8: =OC!P16 -> 0 | E8: =OC!D16 -> 0 | F8: =OC!E16 -> 0 | G8: =C8*F8 -> 0 | H8: =IF(_xlfn.XLOOKUP(A8,[1]MACHOTE!A:A,[1]MACHOTE!V:V,0,0)="S",1.16,IF(_xlfn.XLOOKUP(A8,[1]MACHOTE!A:A,[1]MACHOTE!Y:Y,0,0)="S",1.08,1)) -> 1 | I8: =E8*C8 -> 0 | J8: =G8-I8 -> 0 | K8: =OC!$B$6 -> 0 | L8: =OC!$B$7 -> 0 | M8: =OC!$B$2 -> 0 | N8: =OC!$B$3 -> 0 | O8: =OC!$B$5 -> 0 | P8: =OC!$B$8 -> 0 | Q8: =OC!$B$4 -> 0 | R8: =OC!J16 -> 0 | S8: 0 | T8: =OC!L16 -> 0 | U8: =OC!M16 -> 0 | V8: =OC!N16 -> 0
A9: =OC!A17 -> 0 | B9: =OC!B17 -> 0 | C9: =OC!C17 -> 0 | D9: =OC!P17 -> 0 | E9: =OC!D17 -> 0 | F9: =OC!E17 -> 0 | G9: =C9*F9 -> 0 | H9: =IF(_xlfn.XLOOKUP(A9,[1]MACHOTE!A:A,[1]MACHOTE!V:V,0,0)="S",1.16,IF(_xlfn.XLOOKUP(A9,[1]MACHOTE!A:A,[1]MACHOTE!Y:Y,0,0)="S",1.08,1)) -> 1 | I9: =E9*C9 -> 0 | J9: =G9-I9 -> 0 | K9: =OC!$B$6 -> 0 | L9: =OC!$B$7 -> 0 | M9: =OC!$B$2 -> 0 | N9: =OC!$B$3 -> 0 | O9: =OC!$B$5 -> 0 | P9: =OC!$B$8 -> 0 | Q9: =OC!$B$4 -> 0 | R9: =OC!J17 -> 0 | S9: 0 | T9: =OC!L17 -> 0 | U9: =OC!M17 -> 0 | V9: =OC!N17 -> 0
A10: =OC!A18 -> 0 | B10: =OC!B18 -> 0 | C10: =OC!C18 -> 0 | D10: =OC!P18 -> 0 | E10: =OC!D18 -> 0 | F10: =OC!E18 -> 0 | G10: =C10*F10 -> 0 | H10: =IF(_xlfn.XLOOKUP(A10,[1]MACHOTE!A:A,[1]MACHOTE!V:V,0,0)="S",1.16,IF(_xlfn.XLOOKUP(A10,[1]MACHOTE!A:A,[1]MACHOTE!Y:Y,0,0)="S",1.08,1)) -> 1 | I10: =E10*C10 -> 0 | J10: =G10-I10 -> 0 | K10: =OC!$B$6 -> 0 | L10: =OC!$B$7 -> 0 | M10: =OC!$B$2 -> 0 | N10: =OC!$B$3 -> 0 | O10: =OC!$B$5 -> 0 | P10: =OC!$B$8 -> 0 | Q10: =OC!$B$4 -> 0 | R10: =OC!J18 -> 0 | S10: 0 | T10: =OC!L18 -> 0 | U10: =OC!M18 -> 0 | V10: =OC!N18 -> 0
A11: =OC!A19 -> 0 | B11: =OC!B19 -> 0 | C11: =OC!C19 -> 0 | D11: =OC!P19 -> 0 | E11: =OC!D19 -> 0 | F11: =OC!E19 -> 0 | G11: =C11*F11 -> 0 | H11: =IF(_xlfn.XLOOKUP(A11,[1]MACHOTE!A:A,[1]MACHOTE!V:V,0,0)="S",1.16,IF(_xlfn.XLOOKUP(A11,[1]MACHOTE!A:A,[1]MACHOTE!Y:Y,0,0)="S",1.08,1)) -> 1 | I11: =E11*C11 -> 0 | J11: =G11-I11 -> 0 | K11: =OC!$B$6 -> 0 | L11: =OC!$B$7 -> 0 | M11: =OC!$B$2 -> 0 | N11: =OC!$B$3 -> 0 | O11: =OC!$B$5 -> 0 | P11: =OC!$B$8 -> 0 | Q11: =OC!$B$4 -> 0 | R11: =OC!J19 -> 0 | S11: 0 | T11: =OC!L19 -> 0 | U11: =OC!M19 -> 0 | V11: =OC!N19 -> 0
A12: =OC!A20 -> 0 | B12: =OC!B20 -> 0 | C12: =OC!C20 -> 0 | D12: =OC!P20 -> 0 | E12: =OC!D20 -> 0 | F12: =OC!E20 -> 0 | G12: =C12*F12 -> 0 | H12: =IF(_xlfn.XLOOKUP(A12,[1]MACHOTE!A:A,[1]MACHOTE!V:V,0,0)="S",1.16,IF(_xlfn.XLOOKUP(A12,[1]MACHOTE!A:A,[1]MACHOTE!Y:Y,0,0)="S",1.08,1)) -> 1 | I12: =E12*C12 -> 0 | J12: =G12-I12 -> 0 | K12: =OC!$B$6 -> 0 | L12: =OC!$B$7 -> 0 | M12: =OC!$B$2 -> 0 | N12: =OC!$B$3 -> 0 | O12: =OC!$B$5 -> 0 | P12: =OC!$B$8 -> 0 | Q12: =OC!$B$4 -> 0 | R12: =OC!J20 -> 0 | S12: 0 | T12: =OC!L20 -> 0 | U12: =OC!M20 -> 0 | V12: =OC!N20 -> 0
A13: =OC!A21 -> 0 | B13: =OC!B21 -> 0 | C13: =OC!C21 -> 0 | D13: =OC!P21 -> 0 | E13: =OC!D21 -> 0 | F13: =OC!E21 -> 0 | G13: =C13*F13 -> 0 | H13: =IF(_xlfn.XLOOKUP(A13,[1]MACHOTE!A:A,[1]MACHOTE!V:V,0,0)="S",1.16,IF(_xlfn.XLOOKUP(A13,[1]MACHOTE!A:A,[1]MACHOTE!Y:Y,0,0)="S",1.08,1)) -> 1 | I13: =E13*C13 -> 0 | J13: =G13-I13 -> 0 | K13: =OC!$B$6 -> 0 | L13: =OC!$B$7 -> 0 | M13: =OC!$B$2 -> 0 | N13: =OC!$B$3 -> 0 | O13: =OC!$B$5 -> 0 | P13: =OC!$B$8 -> 0 | Q13: =OC!$B$4 -> 0 | R13: =OC!J21 -> 0 | S13: 0 | T13: =OC!L21 -> 0 | U13: =OC!M21 -> 0 | V13: =OC!N21 -> 0
A14: =OC!A22 -> 0 | B14: =OC!B22 -> 0 | C14: =OC!C22 -> 0 | D14: =OC!P22 -> 0 | E14: =OC!D22 -> 0 | F14: =OC!E22 -> 0 | G14: =C14*F14 -> 0 | H14: =IF(_xlfn.XLOOKUP(A14,[1]MACHOTE!A:A,[1]MACHOTE!V:V,0,0)="S",1.16,IF(_xlfn.XLOOKUP(A14,[1]MACHOTE!A:A,[1]MACHOTE!Y:Y,0,0)="S",1.08,1)) -> 1 | I14: =E14*C14 -> 0 | J14: =G14-I14 -> 0 | K14: =OC!$B$6 -> 0 | L14: =OC!$B$7 -> 0 | M14: =OC!$B$2 -> 0 | N14: =OC!$B$3 -> 0 | O14: =OC!$B$5 -> 0 | P14: =OC!$B$8 -> 0 | Q14: =OC!$B$4 -> 0 | R14: =OC!J22 -> 0 | S14: 0 | T14: =OC!L22 -> 0 | U14: =OC!M22 -> 0 | V14: =OC!N22 -> 0
A15: =OC!A23 -> 0 | B15: =OC!B23 -> 0 | C15: =OC!C23 -> 0 | D15: =OC!P23 -> 0 | E15: =OC!D23 -> 0 | F15: =OC!E23 -> 0 | G15: =C15*F15 -> 0 | H15: =IF(_xlfn.XLOOKUP(A15,[1]MACHOTE!A:A,[1]MACHOTE!V:V,0,0)="S",1.16,IF(_xlfn.XLOOKUP(A15,[1]MACHOTE!A:A,[1]MACHOTE!Y:Y,0,0)="S",1.08,1)) -> 1 | I15: =E15*C15 -> 0 | J15: =G15-I15 -> 0 | K15: =OC!$B$6 -> 0 | L15: =OC!$B$7 -> 0 | M15: =OC!$B$2 -> 0 | N15: =OC!$B$3 -> 0 | O15: =OC!$B$5 -> 0 | P15: =OC!$B$8 -> 0 | Q15: =OC!$B$4 -> 0 | R15: =OC!J23 -> 0 | S15: 0 | T15: =OC!L23 -> 0 | U15: =OC!M23 -> 0 | V15: =OC!N23 -> 0
A16: =OC!A24 -> 0 | B16: =OC!B24 -> 0 | C16: =OC!C24 -> 0 | D16: =OC!P24 -> 0 | E16: =OC!D24 -> 0 | F16: =OC!E24 -> 0 | G16: =C16*F16 -> 0 | H16: =IF(_xlfn.XLOOKUP(A16,[1]MACHOTE!A:A,[1]MACHOTE!V:V,0,0)="S",1.16,IF(_xlfn.XLOOKUP(A16,[1]MACHOTE!A:A,[1]MACHOTE!Y:Y,0,0)="S",1.08,1)) -> 1 | I16: =E16*C16 -> 0 | J16: =G16-I16 -> 0 | K16: =OC!$B$6 -> 0 | L16: =OC!$B$7 -> 0 | M16: =OC!$B$2 -> 0 | N16: =OC!$B$3 -> 0 | O16: =OC!$B$5 -> 0 | P16: =OC!$B$8 -> 0 | Q16: =OC!$B$4 -> 0 | R16: =OC!J24 -> 0 | S16: 0 | T16: =OC!L24 -> 0 | U16: =OC!M24 -> 0 | V16: =OC!N24 -> 0
... A225: =OC!A233 -> 0 | B225: =OC!B233 -> 0 | C225: =OC!C233 -> 0 | D225: =OC!P233 -> 0 | E225: =OC!D233 -> 0 | F225: =OC!E233 -> 0 | G225: =C225*F225 -> 0 | H225: =IF(_xlfn.XLOOKUP(A225,[1]MACHOTE!A:A,[1]MACHOTE!V:V,0,0)="S",1.16,IF(_xlfn.XLOOKUP(A225,[1]MACHOTE!A:A,[1]MACHOTE!Y:Y,0,0)="S",1.08,1)) -> 1 | I225: =E225*C225 -> 0 | J225: =G225-I225 -> 0 | K225: =OC!$B$6 -> 0 | L225: =OC!$B$7 -> 0 | M225: =OC!$B$2 -> 0 | N225: =OC!$B$3 -> 0 | O225: =OC!$B$5 -> 0 | P225: =OC!$B$8 -> 0 | Q225: =OC!$B$4 -> 0 | R225: =OC!J233 -> 0 | S225: 0 | T225: =OC!L233 -> 0 | U225: =OC!M233 -> 0 | V225: =OC!N233 -> 0

Sheet MACHOTE
A1: CLAVE | B1: CLAVE ALTERNA | C1: DESCRIPCION | D1: SERVICIO (S/N) | E1: INV_MIN | F1: INV_MAX | G1: PRECIO COMPRA | H1: PRECIO 1 | I1: PRECIO 2 | J1: MAYOREO 2 | K1: PRECIO 3 | L1: MAYOREO 3 | M1: PRECIO 4 | N1: MAYOREO 4 | O1: EXIST. | P1: PESO | Q1: CARACTERISTICAS | R1: DEPARTAMENTO | S1: CATEGORIA | T1: RECETA (S/N) | U1: GRANEL (S/N) | V1: IMPUESTO (S/N) | W1: IMP IVA 0(S/N) | X1: IMP IVA(S/N) | Y1: IMP IEPS(S/N)
A2: 780083142506 | C2: loperamida - DILOSTOP - 12 tab - 2 mg - COLLINS | D2: false | E2: 5 | F2: 6 | G2: 8.960 | H2: 16.000000 | I2: 9.700000 | J2: 10.000 | K2: 9.700000 | L2: 15.000 | M2: 9.700000 | N2: 20.000 | O2: 0.0000 | P2: 0.0000 | Q2: LOPERAMIDA | R2: GENERICO | S2: TABLETA | T2: N | U2: N | V2: N | W2: S | X2: N | Y2: N
A3: 7502009740992 | C3: amoxicilina/ácido clavulánico - CLAMOXÍN - 10 tab - 500/125 mg - MAVER | D3: false | E3: 364 | F3: 727 | G3: 43.870 | H3: 62.670000 | I3: 47.856000 | J3: 10.000 | K3: 47.856000 | L3: 15.000 | M3: 47.856000 | N3: 20.000 | O3: 0.0000 | P3: 0.0000 | Q3: AMOXICLAV, CLAVULIN, AUGMENTIN, CLAVIPEN, GIMACLAV,VALCLAN, ACROXIL C, GRAMAXIN | R3: ANTIBIOTICO GENERICO | S3: TABLETA | T3: S | U3: N | V3: N | W3: S | X3: N | Y3: N
A4: 7502004401409 | C4: dexametasona/neomicina/fenilefrina - DEXNE NASAL - sol 1 mg/3.5mg/2.5 mg /1 ml - OFFENBACH - flyer | D4: false | E4: 10 | F4: 20 | G4: 30.250 | H4: 45.000000 | I4: 33.690000 | J4: 10.000 | K4: 33.690000 | L4: 15.000 | M4: 33.690000 | N4: 20.000 | O4: 0.0000 | P4: 0.0000 | Q4: ALIN NASAL | R4: GENERICO | S4: OFTALMICO | T4: N | U4: N | V4: N | W4: S | X4: N | Y4: N
A5: 7502227424407 | C5: ibuprofeno - ALGIDOL - 10 cap - 200 mg - GELpharma | D5: false | E5: 56 | F5: 111 | G5: 10.990 | H5: 16.000000 | I5: 12.000000 | J5: 10.000 | K5: 12.000000 | L5: 15.000 | M5: 12.000000 | N5: 20.000 | O5: 0.0000 | P5: 0.0000 | Q5: ADVIL, EUFENIL, GELUBRIN, ACTRON | R5: GENERICO | S5: GENERICO | T5: N | U5: N | V5: N | W5: S | X5: N | Y5: N
A6: 7501537102845 | C6: diclofenaco - NEDICLON LP - 20 tab - 100 mg - BRULUART | D6: false | E6: 523 | F6: 1046 | G6: 6.630 | H6: 19.000000 | I6: 7.000000 | J6: 10.000 | K6: 7.000000 | L6: 15.000 | M6: 7.000000 | N6: 20.000 | O6: 0.0000 | P6: 0.0000 | Q6: VOLTAREN RETARD, MAFENA RETARD, DICLOEFENACO ULTRA, DOCRIL, VOLFENAC | R6: OTC GENERICO | S6: MEDICAMENTO FRACCION VI | T6: N | U6: N | V6: N | W6: S | X6: N | Y6: N
A7: 7502211784197 | C7: bencidamina - BENIFLANT - 360 ml - sol 0.15 g/100 ml - LOEFFLER | D7: false | E7: 151 | F7: 301 | G7: 38.770 | H7: 67.000000 | I7: 42.750000 | J7: 10.000 | K7: 42.750000 | L7: 15.000 | M7: 42.750000 | N7: 20.000 | O7: 0.0000 | P7: 0.0000 | Q7: VANTAL BUCOFARINGEO, ARTROBEN, BIOBEND | R7: GENERICO | S7: GENERICO | T7: N | U7: N | V7: N | W7: S | X7: N | Y7: N
A8: 785120754858 | C8: atorvastatina - ATORLIP - 10 tab -40 mg - MAVI | D8: false | E8: 34 | F8: 68 | G8: 36.360 | H8: 50.000000 | I8: 39.615000 | J8: 10.000 | K8: 39.615000 | L8: 15.000 | M8: 39.615000 | N8: 20.000 | O8: 0.0000 | P8: 0.0000 | Q8: THOREVA, LIPITOR, BACAT, ODIVITOR, TEINEMIA, ETURION | R8: GENERICO | S8: TABLETA | T8: N | U8: N | V8: N | W8: S | X8: N | Y8: N
A9: 7503003738732 | C9: fluoxetina - ZATIN - 30 cap - 20 mg - WERMAR | D9: false | E9: 42 | F9: 83 | G9: 22.000 | H9: 35.000000 | I9: 25.650000 | J9: 10.000 | K9: 25.650000 | L9: 15.000 | M9: 25.650000 | N9: 20.000 | O9: 0.0000 | P9: 0.0000 | Q9: FARMAXETINA,FLUOXAC, PISAURIT, PROZAC 20, ANIUP, F EXINA, VICSEL, INDOZUL | R9: GENERICO | S9: GENERICO | T9: N | U9: N | V9: N | W9: S | X9: N | Y9: N
A10: 785120754810 | C10: atorvastatina - ATORLIP - 10 tab - 20 mg - MAVI | D10: false | E10: 41 | F10: 82 | G10: 25.670 | H10: 38.000000 | I10: 28.130000 | J10: 10.000 | K10: 28.130000 | L10: 15.000 | M10: 28.130000 | N10: 20.000 | O10: 0.0000 | P10: 0.0000 | Q10: THOREVA, LIPITOR, BACAT, ODIVITOR, TEINEMIA, ETURION | R10: GENERICO | S10: TABLETA | T10: N | U10: N | V10: N | W10: S | X10: N | Y10: N
A11: 7501249600813 | C11: levotiroxina sódica - LEVOTIROXINA - 100 tab - 100 mcg - TEMPUSPHARMA | D11: false | E11: 0 | F11: 0 | G11: 41.010 | H11: 58.000000 | I11: 44.160000 | J11: 10.000 | K11: 44.160000 | L11: 15.000 | M11: 44.160000 | N11: 20.000 | O11: 0.0000 | P11: 0.0000 | Q11: EUTIROX, KARET, LEVOTIROXINA SODICA 100 AMSA | R11: GENERICO | S11: GENERICO | T11: N | U11: N | V11: N | W11: S | X11: N | Y11: N
A12: 7501563310436 | C12: tetraciclina - BIOTRICINA - 10 tab - 250 mg - BIORESEARCH | D12: false | E12: 37 | F12: 74 | G12: 11.490 | H12: 20.000000 | I12: 12.446000 | J12: 10.000 | K12: 12.446000 | L12: 15.000 | M12: 12.446000 | N12: 20.000 | O12: 0.0000 | P12: 0.0000 | Q12: ACROMICINA, | R12: ANTIBIOTICO GENERICO | S12: TABLETA | T12: S | U12: N | V12: N | W12: S | X12: N | Y12: N
A13: 7502254000339 | C13: sertralina - ACORTRAL - 14 tab - 50 mg - ACCORD | D13: false | E13: 130 | F13: 259 | G13: 24.720 | H13: 39.500000 | I13: 28.025000 | J13: 10.000 | K13: 28.025000 | L13: 15.000 | M13: 28.025000 | N13: 20.000 | O13: 0.0000 | P13: 0.0000 | Q13: ALTRULINE, EQUIVAC,RESTERAL, SERENATA, TTRESSVIN, ALUPREX, TRAKOS | R13: GENERICO | S13: TABLETA | T13: N | U13: N | V13: N | W13: S | X13: N | Y13: N
... A23: 7502216792760 | C23: omeprazol - OMEPRAZOL - 30 cap - 20 mg - ULTRA | D23: false | E23: 62 | F23: 124 | G23: 14.970 | H23: 25.000000 | I23: 18.525000 | J23: 10.000 | K23: 18.525000 | L23: 15.000 | M23: 18.525000 | N23: 20.000 | O23: 0.0000 | P23: 0.0000 | Q23: ULTIZOL, CIZOLE, GASTROPAX NF, FABOACID PLUS, TASEC, REFLUPRAZOL, CLANZOL 20, ALBOZ | R23: GENERICO | S23: GENERICO | T23: N | U23: N | V23: N | W23: S | X23: N | Y23: N
A24: 7502216804814 | C24: AMLODIPINO - 100 tab - 5 mg - AVIVIA | D24: false | E24: 37 | F24: 74 | G24: 29.300 | H24: 48.000000 | I24: 31.525000 | J24: 10.000 | K24: 31.525000 | L24: 15.000 | M24: 31.525000 | N24: 20.000 | O24: 0.0000 | P24: 0.0000 | R24: GENERICO | S24: TABLETA | T24: N | U24: N | V24: N | W24: S | X24: N | Y24: N
A25: 7501573908104 | C25: naproxeno - BIXEN - 12 tab - 550 mg - BIOMEP | D25: false | E25: 159 | F25: 317 | G25: 19.360 | H25: 36.000000 | I25: 21.342000 | J25: 10.000 | K25: 21.342000 | L25: 15.000 | M25: 21.342000 | N25: 20.000 | O25: 0.0000 | P25: 0.0000 | Q25: FLANAX, DAFLOXEN, ALLIVIAX, INFLANOX,FLAXENDOL | R25: GENERICO | S25: TABLETA | T25: N | U25: N | V25: N | W25: S | X25: N | Y25: N
A26: 7501573900542 | C26: metronidazol - MESSELDAZOL - 30 tab - 500 mg - BIOMEP | D26: false | E26: 58 | F26: 116 | G26: 14.950 | H26: 27.000000 | I26: 16.320000 | J26: 10.000 | K26: 16.320000 | L26: 15.000 | M26: 16.320000 | N26: 20.000 | O26: 0.0000 | P26: 0.0000 | Q26: FLAGENASE, FLAGYL, LAMBLIT | R26: GENERICO | S26: GENERICO | T26: N | U26: N | V26: N | W26: S | X26: N | Y26: N
A27: 7501573900016 | C27: metronidazol - MESSELDAZOL - 20 tab - 500 mg - BIOMEP | D27: false | E27: 39 | F27: 77 | G27: 12.330 | H27: 20.000000 | I27: 13.110000 | J27: 10.000 | K27: 13.110000 | L27: 15.000 | M27: 13.110000 | N27: 20.000 | O27: 0.0000 | P27: 0.0000 | R27: GENERICO | S27: TABLETA | T27: N | U27: N | V27: N | W27: S | X27: N | Y27: N
A28: 7501573900252 | C28: metformina/glibenclamida - WADIL - 30 tab - 500/5 mg - BIOMEP | D28: false | E28: 12 | F28: 23 | G28: 25.960 | H28: 37.000000 | I28: 28.416000 | J28: 10.000 | K28: 28.416000 | L28: 15.000 | M28: 28.416000 | N28: 20.000 | O28: 0.0000 | P28: 0.0000 | Q28: DIMEFOR G, SIL NORBORAL, GLUCOVANCE, MAVIGLIN | R28: GENERICO | S28: TABLETA | T28: N | U28: N | V28: N | W28: S | X28: N | Y28: N
A29: 7501537102111 | C29: ambroxol - OXOLVAN - 20 tab - 30 mg - BRULUART | D29: false | E29: 108 | F29: 324 | G29: 9.300 | H29: 18.000000 | I29: 10.088000 | J29: 10.000 | K29: 10.088000 | L29: 15.000 | M29: 10.088000 | N29: 20.000 | O29: 0.0000 | P29: 0.0000 | Q29: MUCOVIBROL, MUCOANGIN, CLOXAN, OXOLVAN | R29: GENERICO | S29: GENERICO | T29: N | U29: N | V29: N | W29: S | X29: N | Y29: N
A30: 7501590222214 | C30: ácido fólico - MATERFOL - 90 tab - 400 mcg - CMD | D30: false | E30: 19 | F30: 38 | G30: 18.320 | H30: 29.000000 | I30: 19.872000 | J30: 10.000 | K30: 19.872000 | L30: 15.000 | M30: 19.872000 | N30: 20.000 | O30: 0.0000 | P30: 0.0000 | Q30: A.F. VALDECASAS, FOLIVITAL | R30: GENERICO | S30: TABLETA | T30: N | U30: N | V30: N | W30: S | X30: N | Y30: N
A31: 7501590282829 | C31: vit, min, quercetina y omega 3,6 - DIBENEL MAX - 30 cap - 1.35 g c/u - CMD--- | D31: false | E31: 3 | F31: 5 | G31: 50.830 | H31: 73.276000 | I31: 55.034000 | J31: 10.000 | K31: 55.034000 | L31: 15.000 | M31: 55.034000 | N31: 20.000 | O31: 0.0000 | P31: 0.0000 | R31: GENERICO | S31: GENERICO | T31: N | U31: N | V31: S | W31: N | X31: N | Y31: N
A32: 7501590283956 | C32: Omega 3, 6, 9 - OMG 3 - 60 cap - 1.6 g - CMD | D32: false | E32: 18 | F32: 35 | G32: 86.020 | H32: 113.793000 | I32: 93.517000 | J32: 10.000 | K32: 93.517000 | L32: 15.000 | M32: 93.517000 | N32: 20.000 | O32: 0.0000 | P32: 0.0000 | R32: SUPLEMENTOS Y VITAMINAS | S32: SUPLEMENTOS Y VITAMINAS | T32: N | U32: N | V32: S | W32: N | X32: N | Y32: N
A33: 780083141585 | C33: aciclovir - SOVICLOR - tubo 5 g - 50 mg/1 g - COLLINS | D33: false | E33: 57 | F33: 113 | G33: 17.770 | H33: 25.000000 | I33: 19.200000 | J33: 10.000 | K33: 19.200000 | L33: 15.000 | M33: 19.200000 | N33: 20.000 | O33: 0.0000 | P33: 0.0000 | Q33: CICLOFERON, EUROVIR, CLOVEX, LESACLOR, ZIVERONE | R33: GENERICO | S33: GENERICO | T33: N | U33: N | V33: N | W33: S | X33: N | Y33: N
A34: 780083146818 | C34: Losartán-STAARS*-30 compr-50mg - COLLINS--- | D34: false | E34: 0 | F34: 0 | G34: 0.100 | H34: 35.000000 | I34: 27.900000 | J34: 10.000 | K34: 27.400000 | L34: 15.000 | M34: 0.000000 | N34: 20.000 | O34: 0.0000 | P34: 0.0000 | Q34: LODESTAR, ALDERAN, PUNAB, | R34: DESCONTINUADO | S34: DESCONTINUADO | T34: N | U34: N | V34: N | W34: S | X34: N | Y34: N
A35: 780083141066 | C35: diclofenaco - VOLFENAC - gel 1.235 % - tubo 60 g - COLLINS | D35: false | E35: 66 | F35: 132 | G35: 22.580 | H35: 35.000000 | I35: 24.480000 | J35: 10.000 | K35: 24.480000 | L35: 15.000 | M35: 24.480000 | N35: 20.000 | O35: 0.0000 | P35: 0.0000 | Q35: VOLTAREN, FENAGEL | R35: GENERICO | S35: GENERICO | T35: N | U35: N | V35: N | W35: S | X35: N | Y35: N
A36: 780083141929 | C36: ibuprofeno - DOLPRIN - susp - 2 g/100 ml - COLLINS | D36: false | E36: 220 | F36: 439 | G36: 23.530 | H36: 35.000000 | I36: 25.650000 | J36: 10.000 | K36: 25.650000 | L36: 15.000 | M36: 25.650000 | N36: 20.000 | O36: 0.0000 | P36: 0.0000 | Q36: ACTRON, MOTRIM, TABALON,AFLENO, AFLUSIL, DOLVER | R36: GENERICO | S36: GENERICO | T36: N | U36: N | V36: N | W36: S | X36: N | Y36: N
A37: 7502214983375 | C37: levonorgestrel - LEVONORGESTREL - 1 tab - 1.5 mg - DKT | D37: false | E37: 111 | F37: 221 | G37: 14.490 | H37: 25.000000 | I37: 16.281000 | J37: 10.000 | K37: 16.281000 | L37: 15.000 | M37: 16.281000 | N37: 20.000 | O37: 0.0000 | P37: 0.0000 | R37: GENERICO | S37: TABLETA | T37: N | U37: N | V37: N | W37: S | X37: N | Y37: N
A38: 75049805 | C38: neomicina - NEOMICINA/POLIMIXINA B/GRAMICIDINA - sol oft 15 ml - 1.75 mg - OPKO | D38: false | E38: 57 | F38: 114 | G38: 36.530 | H38: 49.000000 | I38: 39.850000 | J38: 10.000 | K38: 39.850000 | L38: 15.000 | M38: 39.850000 | N38: 20.000 | O38: 0.0000 | P38: 0.0000 | Q38: POLIXIN, SEPTILISIN, SULNED | R38: OFTÁLMICO | S38: OFTÁLMICO | T38: N | U38: N | V38: N | W38: S | X38: N | Y38: N
A39: 7501842952890 | C39: ibuprofeno - ADOPREN - 10 tab - 800 mg - GENETICA | D39: false | E39: 47 | F39: 94 | G39: 18.120 | H39: 29.000000 | I39: 20.900000 | J39: 10.000 | K39: 20.900000 | L39: 15.000 | M39: 20.900000 | N39: 20.000 | O39: 0.0000 | P39: 0.0000 | R39: GENERICO | S39: TABLETA | T39: N | U39: N | V39: N | W39: S | X39: N | Y39: N
A40: 7501842900884 | C40: tramadol - GENCATROL RTD - 10 tab - 100 mg - GENÉTICA | D40: false | E40: 46 | F40: 92 | G40: 40.210 | H40: 54.000000 | I40: 46.550000 | J40: 10.000 | K40: 46.550000 | L40: 15.000 | M40: 46.550000 | N40: 20.000 | O40: 0.0000 | P40: 0.0000 | Q40: TRADOL RETARD, DESIGORT 100 | R40: GENERICO | S40: TABLETA | T40: N | U40: N | V40: N | W40: S | X40: N | Y40: N
A41: 7501842901010 | C41: tramadol - GENCATROL - 10 caps - 50 mg - GENÉTICA | D41: false | E41: 63 | F41: 125 | G41: 17.970 | H41: 35.000000 | I41: 20.425000 | J41: 10.000 | K41: 20.425000 | L41: 15.000 | M41: 20.425000 | N41: 20.000 | O41: 0.0000 | P41: 0.0000 | Q41: TRADOL, ADIOLOL | R41: GENERICO | S41: GENERICO | T41: N | U41: N | V41: N | W41: S | X41: N | Y41: N
A42: 7501385490521 | C42: amoxicillina - AMOXICILINA - 12 cap - 500 mg - HORMONA | D42: false | E42: 130 | F42: 260 | G42: 17.000 | H42: 32.000000 | I42: 23.275000 | J42: 10.000 | K42: 23.275000 | L42: 15.000 | M42: 23.275000 | N42: 20.000 | O42: 0.0000 | P42: 0.0000 | R42: ANTIBIOTICO GENERICO | S42: ANTIBIOTICO | T42: S | U42: N | V42: N | W42: S | X42: N | Y42: N
A43: 7501385490316 | C43: ampicilina - AMPICILINA - 20 cap - 500 mg - HORMONA | D43: false | E43: 291 | F43: 581 | G43: 23.390 | H43: 35.000000 | I43: 25.440000 | J43: 10.000 | K43: 25.440000 | L43: 15.000 | M43: 25.440000 | N43: 20.000 | O43: 0.0000 | P43: 0.0000 | Q43: BINOTAL, BRUPEN,MEXAPIN, PENTREXYL | R43: ANTIBIOTICO GENERICO | S43: ANTIBIOTICO | T43: S | U43: N | V43: N | W43: S | X43: N | Y43: N
A44: 7506022315281 | C44: PRUEBA DE EMBARAZO (MEDITEST) - JAYOR | D44: false | E44: 135 | F44: 270 | G44: 14.180 | H44: 20.259000 | I44: 14.628000 | J44: 10.000 | K44: 14.628000 | L44: 15.000 | M44: 14.628000 | N44: 20.000 | O44: 0.0000 | P44: 0.0000 | R44: PREHOSPITALARIO | S44: PREHOSPITALRIO | T44: N | U44: N | V44: S | W44: N | X44: N | Y44: N
A45: 7502225092486 | C45: levofloxacino - CINA - 7 tab - 750 mg - LANDSTEINER | D45: false | E45: 35 | F45: 70 | G45: 24.710 | H45: 45.000000 | I45: 28.025000 | J45: 10.000 | K45: 28.025000 | L45: 15.000 | M45: 28.025000 | N45: 20.000 | O45: 0.0000 | P45: 0.0000 | Q45: BREDELIN, ELEQUINE, FLUONING, MAXIPLINA, LEFLOXINPROXSAFLO, SIBOFIX, UNIQUIN | R45: ANTIBIOTICO GENERICO | S45: TABLETA | T45: S | U45: N | V45: N | W45: S | X45: N | Y45: N
A46: 7501836000828 | C46: sulfadiazina de plata - ARGENTAL - crema 28 g - 1/100 g - LIFERPAL | D46: false | E46: 25 | F46: 50 | G46: 31.550 | H46: 45.000000 | I46: 34.560000 | J46: 10.000 | K46: 34.560000 | L46: 15.000 | M46: 34.560000 | N46: 20.000 | O46: 0.0000 | P46: 0.0000 | Q46: ARGENTAFIL, ARGEMOL | R46: GENERICO | S46: GENERICO | T46: N | U46: N | V46: N | W46: S | X46: N | Y46: N
A47: 7501836000118 | C47: metocarbamol/paracetamol - CARBAFEN - 30 tab - 400/350 mg - LIFERPAL | D47: false | E47: 7 | F47: 13 | G47: 37.320 | H47: 52.000000 | I47: 40.320000 | J47: 10.000 | K47: 40.320000 | L47: 15.000 | M47: 40.320000 | N47: 20.000 | O47: 0.0000 | P47: 0.0000 | R47: GENERICO | S47: TABLETA | T47: N | U47: N | V47: N | W47: S | X47: N | Y47: N
A48: 7501836000927 | C48: ketoconazol - TINIAZOL SHAMPOO - 120 ml - 2 g/100 ml - LIFERPAL | D48: false | E48: 35 | F48: 70 | G48: 38.190 | H48: 54.000000 | I48: 42.275000 | J48: 10.000 | K48: 42.275000 | L48: 15.000 | M48: 42.275000 | N48: 20.000 | O48: 0.0000 | P48: 0.0000 | Q48: MEDICASP | R48: GENERICO | S48: GENERICO | T48: N | U48: N | V48: N | W48: S | X48: N | Y48: N
A49: 7502211789345 | C49: metformina - METFORMINA - 40 tab - 500 mg - LOEFFLER | D49: false | E49: 58 | F49: 115 | G49: 26.340 | H49: 37.000000 | I49: 28.615000 | J49: 10.000 | K49: 28.615000 | L49: 15.000 | M49: 28.615000 | N49: 20.000 | O49: 0.0000 | P49: 0.0000 | Q49: DABEX XR, DIMEFOR, FICONAX, GLUCOPHAGE, AKSPRI, MEVICFOR, | R49: GENERICO | S49: TABLETA | T49: N | U49: N | V49: N | W49: S | X49: N | Y49: N
...
